Workbook

Sheet Instructions
A1: How to use this template: | B1: Different tabs included in this spreadsheet:
A3: This template has a variety of tabs for you to track various processes in influencer marketing. Use the parts that you need! | B3: Overview 2025: This sheet is your birds-eye-view of your campaigns month over month. You can update the more detailed sheets and this one should automatically update for you in real time.
A5: Overview 2025 acts as a dashboard for month over month progress and metrics. It should autoupdate with metrics from "General Campaigns 2025" and "Gifting Tracking." Feel free to add, remove, or change anything to make it useful for you. | B5: General Campaigns 2025: This is your campaign overview. There's a lot of information in this tab, from influencer information to content metrics and sales data. You could, in theory, only use this sheet for everything if you didn't want to separate out your different campaigns or if you wanted to just track high-level information. If you prefer to use the other tabs to dive in further, feel free to remove any column that doesn't make sense here.
A6: There is some duplicated information across a few of the different tabs – this is so you can prioritize the tabs that are useful to you. | B6: Contact/Outreach Progress: This tab is pretty straightforward, it's to track your outreach efforts. Here, you can track influencer information, their contact status, last contact date, etc. You can also track baseline prices if you want to.
A7: For example, "General Campaigns 2025" works as a general tracking sheet with a variety of metrics. The other tabs track more specific aspects of your workflow. So if you just wanted a general tracking sheet, you could start with "General Campaigns 2025" and ignore the others. If you wanted something more specific, you could use the other tabs to dive deeper into the day-to-day.
B8: Content and Usage Rights: In this tab, we've got a variety of metrics that you might want to track around content itself. You might want to adjust those metrics depending on what your campaign goals are. We included a bit of sales/CPM/ROI data (that is duplicated from General Campaigns) in case you wanted to see detailed sales data based on each deliverable.
A9: These tabs are centered around generating sales. If your goal is brand awareness, or content generation, or something else, you may want to change the metrics. Track what's important to you. Feel free to update these templates to make them as useful to you as possible.
B13: Gifting Tracking: This tab is specifically for gifting campaigns. Gifting campaigns have unique needs, like tracking codes and shipping information. We thought to include those things so you can track them easily.
B17: Affiliate Tracking: We recognize that maybe you'd like to keep affiliates separate from your paid and gifted campaigns. That's what this tab is for. If it doesn't make sense for you, feel free to ignore it!

Sheet Overview 2025
B1: General Campaigns | I1: Gifting Campaigns
B2: Month | C2: Budget | D2: Code Redemptions | E2: Cost per Code | F2: Sales | G2: CAC | I2: Month | J2: Budget | K2: Code Redemptions | L2: Cost per Code | M2: Sales | N2: ROI
B3: January | C3: ='General Campaigns 2025'!J2 -> 52000 | D3: ='General Campaigns 2025'!R2 -> 425 | E3: =C3/D3 -> 122.35294 | F3: ='General Campaigns 2025'!T2 -> 13000 | G3: =C3/F3 -> 4 | I3: January | J3: ='Gifting Tracking'!O3 -> 4500 | K3: ='Gifting Tracking'!U3 -> 1665 | L3: =J3/K3 -> 2.7027027 | M3: ='Gifting Tracking'!V3 -> 83250 | N3: =M3/J3 -> 18.5
B4: February | C4: ='General Campaigns 2025'!J7 -> 0 | D4: ='General Campaigns 2025'!R7 -> 0 | E4: =C4/D4 -> #DIV/0! | F4: ='General Campaigns 2025'!T7 -> 0 | G4: =C4/F4 -> #DIV/0! | I4: February | J4: ='Gifting Tracking'!O20 -> 0 | K4: ='Gifting Tracking'!U20 -> 0 | L4: =J4/K4 -> #DIV/0! | M4: ='Gifting Tracking'!V20 -> 0 | N4: =J4/M4 -> #DIV/0!
B5: March | C5: ='General Campaigns 2025'!J12 -> 0 | D5: ='General Campaigns 2025'!R12 -> 0 | E5: =C5/D5 -> #DIV/0! | F5: ='General Campaigns 2025'!T12 -> 0 | G5: =C5/F5 -> #DIV/0! | I5: March | J5: ='Gifting Tracking'!O40 -> 0 | K5: ='Gifting Tracking'!U40 -> 0 | L5: =J5/K5 -> #DIV/0! | M5: ='Gifting Tracking'!V40 -> 0 | N5: =J5/M5 -> #DIV/0!
B6: April | C6: ='General Campaigns 2025'!J17 -> 0 | D6: ='General Campaigns 2025'!R17 -> 0 | E6: =C6/D6 -> #DIV/0! | F6: ='General Campaigns 2025'!T17 -> 0 | G6: =C6/F6 -> #DIV/0! | I6: April | J6: ='Gifting Tracking'!O60 -> 0 | K6: ='Gifting Tracking'!U60 -> 0 | L6: =J6/K6 -> #DIV/0! | M6: ='Gifting Tracking'!V60 -> 0 | N6: =J6/M6 -> #DIV/0!
B7: May | C7: ='General Campaigns 2025'!J22 -> 0 | D7: ='General Campaigns 2025'!R22 -> 0 | E7: =C7/D7 -> #DIV/0! | F7: ='General Campaigns 2025'!T22 -> 0 | G7: =C7/F7 -> #DIV/0! | I7: May | J7: ='Gifting Tracking'!O80 -> 0 | K7: ='Gifting Tracking'!U80 -> 0 | L7: =J7/K7 -> #DIV/0! | M7: ='Gifting Tracking'!V80 -> 0 | N7: =J7/M7 -> #DIV/0!
B8: June | C8: ='General Campaigns 2025'!J27 -> 0 | D8: ='General Campaigns 2025'!R27 -> 0 | E8: =C8/D8 -> #DIV/0! | F8: ='General Campaigns 2025'!T27 -> 0 | G8: =C8/F8 -> #DIV/0! | I8: June | J8: ='Gifting Tracking'!O100 -> 0 | K8: ='Gifting Tracking'!U100 -> 0 | L8: =J8/K8 -> #DIV/0! | M8: ='Gifting Tracking'!V100 -> 0 | N8: =J8/M8 -> #DIV/0!
B9: July | C9: ='General Campaigns 2025'!J32 -> 0 | D9: ='General Campaigns 2025'!R32 -> 0 | E9: =C9/D9 -> #DIV/0! | F9: ='General Campaigns 2025'!T32 -> 0 | G9: =C9/F9 -> #DIV/0! | I9: July | J9: ='Gifting Tracking'!O120 -> 0 | K9: ='Gifting Tracking'!U120 -> 0 | L9: =J9/K9 -> #DIV/0! | M9: ='Gifting Tracking'!V120 -> 0 | N9: =J9/M9 -> #DIV/0!
B10: August | C10: ='General Campaigns 2025'!J37 -> 0 | D10: ='General Campaigns 2025'!R37 -> 0 | E10: =C10/D10 -> #DIV/0! | F10: ='General Campaigns 2025'!T37 -> 0 | G10: =C10/F10 -> #DIV/0! | I10: August | J10: ='Gifting Tracking'!O140 -> 0 | K10: ='Gifting Tracking'!U140 -> 0 | L10: =J10/K10 -> #DIV/0! | M10: ='Gifting Tracking'!V140 -> 0 | N10: =J10/M10 -> #DIV/0!
B11: September | C11: ='General Campaigns 2025'!J42 -> 0 | D11: ='General Campaigns 2025'!R42 -> 0 | E11: =C11/D11 -> #DIV/0! | F11: ='General Campaigns 2025'!T42 -> 0 | G11: =C11/F11 -> #DIV/0! | I11: September | J11: ='Gifting Tracking'!O160 -> 0 | K11: ='Gifting Tracking'!U160 -> 0 | L11: =J11/K11 -> #DIV/0! | M11: ='Gifting Tracking'!V160 -> 0 | N11: =J11/M11 -> #DIV/0!
B12: October | C12: ='General Campaigns 2025'!J47 -> 0 | D12: ='General Campaigns 2025'!R47 -> 0 | E12: =C12/D12 -> #DIV/0! | F12: ='General Campaigns 2025'!T47 -> 0 | G12: =C12/F12 -> #DIV/0! | I12: October | J12: ='Gifting Tracking'!O180 -> 0 | K12: ='Gifting Tracking'!U180 -> 0 | L12: =J12/K12 -> #DIV/0! | M12: ='Gifting Tracking'!V180 -> 0 | N12: =J12/M12 -> #DIV/0!
B13: November | C13: ='General Campaigns 2025'!J52 -> 0 | D13: ='General Campaigns 2025'!R52 -> 0 | E13: =C13/D13 -> #DIV/0! | F13: ='General Campaigns 2025'!T52 -> 0 | G13: =C13/F13 -> #DIV/0! | I13: November | J13: ='Gifting Tracking'!O200 -> 0 | K13: ='Gifting Tracking'!U200 -> 0 | L13: =J13/K13 -> #DIV/0! | M13: ='Gifting Tracking'!V200 -> 0 | N13: =J13/M13 -> #DIV/0!
B14: December | C14: ='General Campaigns 2025'!J57 -> 0 | D14: ='General Campaigns 2025'!R57 -> 0 | E14: =C14/D14 -> #DIV/0! | F14: ='General Campaigns 2025'!T57 -> 0 | G14: =C14/F14 -> #DIV/0! | I14: December | J14: ='Gifting Tracking'!O220 -> 0 | K14: ='Gifting Tracking'!U220 -> 0 | L14: =J14/K14 -> #DIV/0! | M14: ='Gifting Tracking'!V220 -> 0 | N14: =J14/M14 -> #DIV/0!
B16: TOTAL: | C16: =SUM(C3:C14) -> 52000 | D16: =SUM(D3:D14) -> 425 | E16: =C16/D16 -> 122.35294 | F16: =SUM(F3:F14) -> 13000 | G16: =C16/F16 -> 4 | I16: TOTAL: | J16: =SUM(J3:J14) -> 4500 | K16: =SUM(K3:K14) -> 1665 | L16: =J16/K16 -> 2.7027027 | M16: =SUM(M3:M14) -> 83250 | N16: =J16/M16 -> 0.054054054
B19: Affiliate Campaigns
B20: Month | C20: Budget | D20: Code Redemptions | E20: Cost per Code | F20: Sales | G20: ROI
B21: January | C21: ='Affiliate Tracking'!L3 -> 4162.5 | D21: ='Affiliate Tracking'!M3 -> 1665 | E21: =C21/D21 -> 2.5 | F21: ='Affiliate Tracking'!N3 -> 83250 | G21: ='Affiliate Tracking'!O3 -> 20
B22: February | C22: ='Affiliate Tracking'!L29 | D22: ='Affiliate Tracking'!M29 | E22: =C22/D22 -> #DIV/0! | F22: ='Affiliate Tracking'!N20 -> 0 | G22: ='Affiliate Tracking'!O20 -> 0
B23: March | C23: ='Affiliate Tracking'!L40 | D23: ='Affiliate Tracking'!M40 -> 0 | E23: =C23/D23 -> #DIV/0! | F23: ='Affiliate Tracking'!N40 -> 0 | G23: ='Affiliate Tracking'!O40 -> 0
B24: April | C24: ='Affiliate Tracking'!L60 | D24: ='Affiliate Tracking'!M60 -> 0 | E24: =C24/D24 -> #DIV/0! | F24: ='Affiliate Tracking'!N60 -> 0 | G24: ='Affiliate Tracking'!O60 -> 0
B25: May | C25: ='Affiliate Tracking'!L80 | D25: ='Affiliate Tracking'!M80 -> 0 | E25: =C25/D25 -> #DIV/0! | F25: ='Affiliate Tracking'!N80 -> 0 | G25: ='Affiliate Tracking'!O80 -> 0
B26: June | C26: ='Affiliate Tracking'!L100 | D26: ='Affiliate Tracking'!M100 -> 0 | E26: =C26/D26 -> #DIV/0! | F26: ='Affiliate Tracking'!N100 -> 0 | G26: ='Affiliate Tracking'!O100 -> 0
B27: July | C27: ='Affiliate Tracking'!L120 | D27: ='Affiliate Tracking'!M120 -> 0 | E27: =C27/D27 -> #DIV/0! | F27: ='Affiliate Tracking'!N120 -> 0 | G27: ='Affiliate Tracking'!O120 -> 0
B28: August | C28: ='Affiliate Tracking'!L140 | D28: ='Affiliate Tracking'!M140 -> 0 | E28: =C28/D28 -> #DIV/0! | F28: ='Affiliate Tracking'!N140 -> 0 | G28: ='Affiliate Tracking'!O140 -> 0
B29: September | C29: ='Affiliate Tracking'!L160 | D29: ='Affiliate Tracking'!M160 -> 0 | E29: =C29/D29 -> #DIV/0! | F29: ='Affiliate Tracking'!N160 -> 0 | G29: ='Affiliate Tracking'!O160 -> 0
B30: October | C30: ='Affiliate Tracking'!L180 | D30: ='Affiliate Tracking'!M180 -> 0 | E30: =C30/D30 -> #DIV/0! | F30: ='Affiliate Tracking'!N180 -> 0 | G30: ='Affiliate Tracking'!O180 -> 0
B31: November | C31: ='Affiliate Tracking'!L200 | D31: ='Affiliate Tracking'!M200 -> 0 | E31: =C31/D31 -> #DIV/0! | F31: ='Affiliate Tracking'!N200 -> 0 | G31: ='Affiliate Tracking'!O200 -> 0
B32: December | C32: ='Affiliate Tracking'!L220 | D32: ='Affiliate Tracking'!M220 -> 0 | E32: =C32/D32 -> #DIV/0! | F32: ='Affiliate Tracking'!N220 -> 0 | G32: ='Affiliate Tracking'!O220 -> 0
B34: TOTAL: | C34: =SUM(C21:C32) -> 4162.5 | D34: =SUM(D21:D32) -> 1665 | E34: =C34/D34 -> 2.5 | F34: =SUM(F21:F32) -> 83250 | G34: =C34/F34 -> 0.05

Sheet General Campaigns 2025
A1: Handle / Account | B1: Email | C1: Market | D1: Status | E1: Platform | F1: Subs | G1: ER | H1: Deliverables | I1: Expected Reach | J1: Budget | K1: CPM | L1: Code | M1: Approval Date | N1: Posting Date | O1: Live Content Link | P1: Actual Reach | Q1: Actual CPM | R1: Code Redemptions | S1: Cost per Code Redemption | T1: Sales | U1: CAC | V1: Invoice Paid
A2: January Conversions | F2: =sum(F3:F5) -> 0 | G2: =average(G3:G5) -> 0.0004 | I2: =sum(I3:I5) -> 400000000 | J2: =sum(J3:J5) -> 52000 | K2: =J2/(I2/1000) -> 0.13 | P2: =sum(P3:P5) -> 325000000 | Q2: =J2/(P2/1000) -> 0.16 | R2: =sum(R3:R5) -> 425 | S2: =J2/R2 -> 122.35294 | T2: =sum(T3:T5) -> 13000 | U2: =J2/T2 -> 4
A3: @therock | B3: Dwayne@therock.com | C3: United States | D3: Signed | E3: IG | G3: 0.0004 | H3: Reel | I3: 400000000 | J3: 52000 | K3: =J3/(I3/1000) -> 0.13 | L3: THEROCK20 | M3: 45664 | P3: 325000000 | Q3: =J3/(P3/1000) -> 0.16 | R3: 425 | S3: =J3/R3 -> 122.35294 | T3: 13000 | U3: =J3/T3 -> 4 | V3: TRUE
K4: =J4/(I4/1000) -> #DIV/0! | Q4: =J4/(P4/1000) -> #DIV/0! | S4: =J4/R4 -> #DIV/0! | U4: =J4/T4 -> #DIV/0! | V4: FALSE
K5: =J5/(I5/1000) -> #DIV/0! | Q5: =J5/(P5/1000) -> #DIV/0! | S5: =J5/R5 -> #DIV/0! | U5: =J5/T5 -> #DIV/0! | V5: FALSE
Q6: =J6/(P6/1000) -> #DIV/0! | S6: =J6/R6 -> #DIV/0! | U6: =J6/T6 -> #DIV/0!
A7: February [Main Goal] | F7: =sum(F8:F10) -> 0 | G7: =average(G8:G10) -> #DIV/0! | I7: =sum(I8:I10) -> 0 | J7: =sum(J8:J10) -> 0 | K7: =J7/(I7/1000) -> #DIV/0! | P7: =sum(P8:P10) -> 0 | Q7: =J7/(P7/1000) -> #DIV/0! | R7: =sum(R8:R10) -> 0 | S7: =J7/R7 -> #DIV/0! | T7: =sum(T8:T10) -> 0 | U7: =J7/T7 -> #DIV/0!
K8: =J8/(I8/1000) -> #DIV/0! | V8: FALSE
K9: =J9/(I9/1000) -> #DIV/0! | V9: FALSE
K10: =J10/(I10/1000) -> #DIV/0! | V10: FALSE
A12: March [Main Goal] | F12: =sum(F13:F15) -> 0 | G12: =average(G13:G15) -> #DIV/0! | I12: =sum(I13:I15) -> 0 | J12: =sum(J13:J15) -> 0 | K12: =J12/(I12/1000) -> #DIV/0! | P12: =sum(P13:P15) -> 0 | Q12: =J12/(P12/1000) -> #DIV/0! | R12: =sum(R13:R15) -> 0 | S12: =J12/R12 -> #DIV/0! | T12: =sum(T13:T15) -> 0 | U12: =J12/T12 -> #DIV/0!
K13: =J13/(I13/1000) -> #DIV/0! | V13: FALSE
K14: =J14/(I14/1000) -> #DIV/0! | V14: FALSE
K15: =J15/(I15/1000) -> #DIV/0! | V15: FALSE
A17: April [Main Goal] | F17: =sum(F18:F20) -> 0 | G17: =average(G18:G20) -> #DIV/0! | I17: =sum(I18:I20) -> 0 | J17: =sum(J18:J20) -> 0 | K17: =J17/(I17/1000) -> #DIV/0! | P17: =sum(P18:P20) -> 0 | Q17: =J17/(P17/1000) -> #DIV/0! | R17: =sum(R18:R20) -> 0 | S17: =J17/R17 -> #DIV/0! | T17: =sum(T18:T20) -> 0 | U17: =J17/T17 -> #DIV/0!
K18: =J18/(I18/1000) -> #DIV/0! | V18: FALSE
K19: =J19/(I19/1000) -> #DIV/0! | V19: FALSE
K20: =J20/(I20/1000) -> #DIV/0! | V20: FALSE
A22: May [Main Goal] | F22: =sum(F23:F25) -> 0 | G22: =average(G23:G25) -> #DIV/0! | I22: =sum(I23:I25) -> 0 | J22: =sum(J23:J25) -> 0 | K22: =J22/(I22/1000) -> #DIV/0! | P22: =sum(P23:P25) -> 0 | Q22: =J22/(P22/1000) -> #DIV/0! | R22: =sum(R23:R25) -> 0 | S22: =J22/R22 -> #DIV/0! | T22: =sum(T23:T25) -> 0 | U22: =J22/T22 -> #DIV/0!
K23: =J23/(I23/1000) -> #DIV/0! | V23: FALSE
K24: =J24/(I24/1000) -> #DIV/0! | V24: FALSE
K25: =J25/(I25/1000) -> #DIV/0! | V25: FALSE
A27: June [Main Goal] | F27: =sum(F28:F30) -> 0 | G27: =average(G28:G30) -> #DIV/0! | I27: =sum(I28:I30) -> 0 | J27: =sum(J28:J30) -> 0 | K27: =J27/(I27/1000) -> #DIV/0! | P27: =sum(P28:P30) -> 0 | Q27: =J27/(P27/1000) -> #DIV/0! | R27: =sum(R28:R30) -> 0 | S27: =J27/R27 -> #DIV/0! | T27: =sum(T28:T30) -> 0 | U27: =J27/T27 -> #DIV/0!
K28: =J28/(I28/1000) -> #DIV/0! | V28: FALSE
K29: =J29/(I29/1000) -> #DIV/0! | V29: FALSE
K30: =J30/(I30/1000) -> #DIV/0! | V30: FALSE
A32: July [Main Goal] | F32: =sum(F33:F35) -> 0 | G32: =average(G33:G35) -> #DIV/0! | I32: =sum(I33:I35) -> 0 | J32: =sum(J33:J35) -> 0 | K32: =J32/(I32/1000) -> #DIV/0! | P32: =sum(P33:P35) -> 0 | Q32: =J32/(P32/1000) -> #DIV/0! | R32: =sum(R33:R35) -> 0 | S32: =J32/R32 -> #DIV/0! | T32: =sum(T33:T35) -> 0 | U32: =J32/T32 -> #DIV/0!
K33: =J33/(I33/1000) -> #DIV/0! | V33: FALSE
K34: =J34/(I34/1000) -> #DIV/0! | V34: FALSE
K35: =J35/(I35/1000) -> #DIV/0! | V35: FALSE
A37: August [Main Goal] | F37: =sum(F38:F40) -> 0 | G37: =average(G38:G40) -> #DIV/0! | I37: =sum(I38:I40) -> 0 | J37: =sum(J38:J40) -> 0 | K37: =J37/(I37/1000) -> #DIV/0! | P37: =sum(P38:P40) -> 0 | Q37: =J37/(P37/1000) -> #DIV/0! | R37: =sum(R38:R40) -> 0 | S37: =J37/R37 -> #DIV/0! | T37: =sum(T38:T40) -> 0 | U37: =J37/T37 -> #DIV/0!
K38: =J38/(I38/1000) -> #DIV/0! | V38: FALSE
K39: =J39/(I39/1000) -> #DIV/0! | V39: FALSE
K40: =J40/(I40/1000) -> #DIV/0! | V40: FALSE
A42: September [Main Goal] | F42: =sum(F43:F45) -> 0 | G42: =average(G43:G45) -> #DIV/0! | I42: =sum(I43:I45) -> 0 | J42: =sum(J43:J45) -> 0 | K42: =J42/(I42/1000) -> #DIV/0! | P42: =sum(P43:P45) -> 0 | Q42: =J42/(P42/1000) -> #DIV/0! | R42: =sum(R43:R45) -> 0 | S42: =J42/R42 -> #DIV/0! | T42: =sum(T43:T45) -> 0 | U42: =J42/T42 -> #DIV/0!
K43: =J43/(I43/1000) -> #DIV/0! | V43: FALSE
K44: =J44/(I44/1000) -> #DIV/0! | V44: FALSE
K45: =J45/(I45/1000) -> #DIV/0! | V45: FALSE
A47: October [Main Goal] | F47: =sum(F48:F50) -> 0 | G47: =average(G48:G50) -> #DIV/0! | I47: =sum(I48:I50) -> 0 | J47: =sum(J48:J50) -> 0 | K47: =J47/(I47/1000) -> #DIV/0! | P47: =sum(P48:P50) -> 0 | Q47: =J47/(P47/1000) -> #DIV/0! | R47: =sum(R48:R50) -> 0 | S47: =J47/R47 -> #DIV/0! | T47: =sum(T48:T50) -> 0 | U47: =J47/T47 -> #DIV/0!
K48: =J48/(I48/1000) -> #DIV/0! | V48: FALSE
...

Sheet Automatic Contact

Sheet ContactOutreach Progress
B2: Handle / Account | C2: Email | D2: Influencer Country | E2: Domain/Niche | F2: Market | G2: Status | H2: Last Contact Date | I2: Platform | J2: Expected Reach | K2: Followers | L2: ER | M2: Price Quoted | N2: Price post Negotiation | O2: Deliverables Agreed Upon
B3: @therock | C3: Dwayne@therock.com | D3: United States | E3: Lifestyle/Health | F3: United States | G3: Signed | H3: 45672 | I3: IG | J3: 394.7M | K3: 394.7M | L3: 0.0004 | M3: 75000 | N3: 52000 | P3: Stories
P4: Reel
P5: TikTok

Sheet Content & Usage Rights
A1: Handle / Account | B1: Market | C1: Platform | D1: Deliverables | E1: Content Approval Date | F1: Posting Date | G1: Live Content Link | H1: Link to Modified Content for Ads | I1: Date Usage Starts | J1: Date Usage Ends | K1: Link to Usage agreement | L1: ER | M1: Impressions | N1: Comments | O1: Likes | P1: Shares | Q1: Saves | R1: Budget | S1: Expected Reach | T1: Actual Reach | U1: Actual CPM | V1: Number of Sales | W1: Amount of Sales | X1: ROI
A2: @therock | B2: United States | C2: IG | D2: Stories | E2: 45671 | F2: 45672 | G2: https://www.instagram.com/p/DE_SumLv5Po/ | H2: https://www.instagram.com/p/DE_SumLv5Po/ | I2: 45659 | J2: 45749 | K2: XX | L2: 0.0158 | M2: XX | N2: 241K | O2: 17.3M | P2: 7K | Q2: 15K | R2: 15000 | S2: 1500000 | T2: 1400000 | U2: =R2/(T2/1000) -> 10.714286 | V2: 220 | W2: 6600 | X2: =W2/R2 -> 0.44
C3: IG | D3: Reel | E3: 45672 | F3: 45673 | G3: https://www.instagram.com/p/DGfTN60RpjN/ | H3: https://www.instagram.com/p/DGfTN60RpjN/ | I3: 45660 | J3: 45750 | K3: XX | L3: 0.0004 | M3: XX | N3: 47.7K | O3: 4.2M | P3: 19K | Q3: 12K | R3: 22000 | S3: 1500000 | T3: 2002500 | U3: =R3/(T3/1000) -> 10.986267 | V3: 138 | W3: 4140 | X3: =W3/R3 -> 0.18818182
C4: TikTok | D4: TikTok | E4: 45673 | F4: 45674 | G4: https://www.tiktok.com/@therock/video/7474681315955150126 | H4: https://www.tiktok.com/@therock/video/7474681315955150127 | I4: 45661 | J4: 45751 | K4: XX | L4: 0.0841 | M4: XX | N4: 168.8K | O4: 3.21M | P4: 3.1M | Q4: 1.6M | R4: 15000 | S4: 5600000 | T4: 7900000 | U4: =R4/(T4/1000) -> 1.8987342 | V4: 101 | W4: 3030 | X4: =W4/R4 -> 0.202
U5: =R5/(T5/1000) -> #DIV/0! | X5: =W5/R5 -> #DIV/0!
U6: =R6/(T6/1000) -> #DIV/0! | X6: =W6/R6 -> #DIV/0!
U7: =R7/(T7/1000) -> #DIV/0! | X7: =W7/R7 -> #DIV/0!
U8: =R8/(T8/1000) -> #DIV/0! | X8: =W8/R8 -> #DIV/0!
U9: =R9/(T9/1000) -> #DIV/0! | X9: =W9/R9 -> #DIV/0!
U10: =R10/(T10/1000) -> #DIV/0! | X10: =W10/R10 -> #DIV/0!
U11: =R11/(T11/1000) -> #DIV/0! | X11: =W11/R11 -> #DIV/0!
U12: =R12/(T12/1000) -> #DIV/0! | X12: =W12/R12 -> #DIV/0!
U13: =R13/(T13/1000) -> #DIV/0! | X13: =W13/R13 -> #DIV/0!
U14: =R14/(T14/1000) -> #DIV/0! | X14: =W14/R14 -> #DIV/0!
U15: =R15/(T15/1000) -> #DIV/0! | X15: =W15/R15 -> #DIV/0!
U16: =R16/(T16/1000) -> #DIV/0! | X16: =W16/R16 -> #DIV/0!
... U45: =R45/(T45/1000) -> #DIV/0! | X45: =W45/R45 -> #DIV/0!
R46: =sum(R47:R49) -> 0 | S46: =sum(S47:S49) -> 0 | U46: =R46/(T46/1000) -> #DIV/0! | X46: =W46/R46 -> #DIV/0!
R47: =sum(R48:R50) -> 0 | S47: =sum(S48:S50) -> 0 | U47: =R47/(T47/1000) -> #DIV/0! | X47: =W47/R47 -> #DIV/0!
R48: =sum(R49:R51) -> 0 | S48: =sum(S49:S51) -> 0 | U48: =R48/(T48/1000) -> #DIV/0! | X48: =W48/R48 -> #DIV/0!

Sheet Gifting Tracking
A1: Handle / Account | B1: Email | C1: Expected Reach | D1: Followers | E1: ER | F1: Influencer Country | G1: Address | H1: Code | I1: Status | J1: Link to Contract/ Agreement | K1: Last Contact Date | L1: Platform | M1: Products chosen | N1: Tracking Number/ Link | O1: Order Total | P1: Status | Q1: Deliverables Agreed Upon | S1: Post Date | T1: Live Content Link | U1: Number of Code Redeems | V1: Sale value | W1: ROI
N2: YTD Total: | O2: =sum(O4:O999) -> 4500 | U2: =sum(U4:U999) -> 1665 | V2: =sum(V4:V999) -> 83250 | W2: =AVERAGE(W3,W20,W40,W60,W80,W100,W120,W140,W160,W180,W200,W220) -> #DIV/0!
A3: January | O3: =SUM(O4:O19) -> 4500 | U3: =SUM(U4:U103) -> 1665 | V3: =SUM(V4:V103) -> 83250 | W3: =AVERAGE(W4:W6) -> 18.5
A4: @therock | B4: Dwayne@therock.com | C4: 394.7M | D4: 394.7M | E4: 0.0004 | F4: United States | G4: 123 Johnson Street, 12378 Hollywood, California | H4: THEROCK20 | I4: Agreed | K4: 45672 | L4: IG, TikTok | M4: SKU | N4: ## | O4: 1500 | P4: Ordered | R4: Stories | U4: 555 | V4: 27750 | W4: =V4/O4 -> 18.5
M5: SKU | N5: ## | O5: 1500 | P5: Processing | R5: Reel | U5: 555 | V5: 27750 | W5: =V5/O5 -> 18.5
M6: SKU | N6: ## | O6: 1500 | P6: Shipped | R6: TikTok | U6: 555 | V6: 27750 | W6: =V6/O6 -> 18.5
A20: February | O20: =SUM(O21:O39) -> 0 | U20: =SUM(U21:U39) -> 0 | V20: =SUM(V21:V39) -> 0 | W20: =AVERAGE(W21:W39) -> #DIV/0!
A40: March | O40: =SUM(O41:O59) -> 0 | U40: =SUM(U41:U59) -> 0 | V40: =SUM(V41:V59) -> 0 | W40: =AVERAGE(W41:W59) -> #DIV/0!
A60: April | O60: =SUM(O61:O79) -> 0 | U60: =SUM(U61:U79) -> 0 | V60: =SUM(V61:V79) -> 0 | W60: =AVERAGE(W61:W79) -> #DIV/0!
A80: May | O80: =SUM(O81:O99) -> 0 | U80: =SUM(U81:U99) -> 0 | V80: =SUM(V81:V99) -> 0 | W80: =AVERAGE(W81:W99) -> #DIV/0!
A100: June | O100: =SUM(O101:O119) -> 0 | U100: =SUM(U101:U119) -> 0 | V100: =SUM(V101:V119) -> 0 | W100: =AVERAGE(W101:W119) -> #DIV/0!
A120: July | O120: =SUM(O121:O139) -> 0 | U120: =SUM(U121:U139) -> 0 | V120: =SUM(V121:V139) -> 0 | W120: =AVERAGE(W121:W139) -> #DIV/0!
A140: August | O140: =SUM(O141:O159) -> 0 | U140: =SUM(U141:U159) -> 0 | V140: =SUM(V141:V159) -> 0 | W140: =AVERAGE(W141:W159) -> #DIV/0!
A160: September | O160: =SUM(O161:O179) -> 0 | U160: =SUM(U161:U179) -> 0 | V160: =SUM(V161:V179) -> 0 | W160: =AVERAGE(W161:W179) -> #DIV/0!
A180: October | O180: =SUM(O181:O199) -> 0 | U180: =SUM(U181:U199) -> 0 | V180: =SUM(V181:V199) -> 0 | W180: =AVERAGE(W181:W199) -> #DIV/0!
A200: November | O200: =SUM(O201:O219) -> 0 | U200: =SUM(U201:U219) -> 0 | V200: =SUM(V201:V219) -> 0 | W200: =AVERAGE(W201:W219) -> #DIV/0!
A220: December | O220: =SUM(O221:O239) -> 0 | U220: =SUM(U221:U239) -> 0 | V220: =SUM(V221:V239) -> 0 | W220: =AVERAGE(W221:W239) -> #DIV/0!

Sheet Affiliate Tracking
A1: Handle / Account | B1: Email | C1: Followers | D1: ER | E1: Influencer Country | F1: Code | G1: Status | H1: Affiliate Discount | I1: Affiliate Code | J1: Affiliate Payout Percent | K1: Platform | L1: Affiliate Payout | M1: Number of Code Redeems | N1: Sale value | O1: ROI
K2: YTD Total: | L2: =sum(L4:L999) -> 4162.5 | M2: =sum(M4:M999) -> 1665 | N2: =sum(N4:N999) -> 83250 | O2: =AVERAGE(O3,O20,O40,O60,O80,O100,O120,O140,O160,O180,O200,O220) -> 1.6666667
A3: January | L3: =sum(L4:L19) -> 4162.5 | M3: =SUM(M4:M103) -> 1665 | N3: =SUM(N4:N103) -> 83250 | O3: =AVERAGE(O4:O6) -> 20
A4: @therock | B4: Dwayne@therock.com | C4: 394.7M | D4: 0.0004 | E4: United States | F4: THEROCK20 | G4: Agreed | H4: 0.15 | I4: THEROCK15 | J4: 0.05 | K4: IG, TikTok | L4: =product(J4*N4) -> 1387.5 | M4: 555 | N4: 27750 | O4: =N4/L4 -> 20
J5: 0.05 | L5: =product(J5*N5) -> 1387.5 | M5: 555 | N5: 27750 | O5: =N5/L5 -> 20
J6: 0.05 | L6: =product(J6*N6) -> 1387.5 | M6: 555 | N6: 27750 | O6: =N6/L6 -> 20
L7: =product(0.05*N7) -> 0 | N7: 0 | O7: =N7/L7 -> #DIV/0!
L8: =product(0.05*N8) -> 0 | N8: 0 | O8: =N8/L8 -> #DIV/0!
L9: =product(0.05*N9) -> 0 | N9: 0 | O9: =N9/L9 -> #DIV/0!
L10: =product(0.05*N10) -> 0 | N10: 0 | O10: =N10/L10 -> #DIV/0!
L11: =product(0.05*N11) -> 0 | N11: 0 | O11: =N11/L11 -> #DIV/0!
L12: =product(0.05*N12) -> 0 | N12: 0 | O12: =N12/L12 -> #DIV/0!
L13: =product(0.05*N13) -> 0 | N13: 0 | O13: =N13/L13 -> #DIV/0!
L14: =product(0.05*N14) -> 0 | N14: 0 | O14: =N14/L14 -> #DIV/0!
L15: =product(0.05*N15) -> 0 | N15: 0 | O15: =N15/L15 -> #DIV/0!
L16: =product(0.05*N16) -> 0 | N16: 0 | O16: =N16/L16 -> #DIV/0!
L17: =product(0.05*N17) -> 0 | N17: 0 | O17: =N17/L17 -> #DIV/0!
L18: =product(0.05*N18) -> 0 | N18: 0 | O18: =N18/L18 -> #DIV/0!
L19: =product(0.05*N19) -> 0 | N19: 0 | O19: =N19/L19 -> #DIV/0!
A20: February | M20: =SUM(M21:M39) -> 0 | N20: =SUM(N21:N39) -> 0 | O20: =AVERAGE(O21:O39) -> 0
O21: 0
A40: March | M40: =SUM(M41:M59) -> 0 | N40: =SUM(N41:N59) -> 0 | O40: =AVERAGE(O41:O59) -> 0
O41: 0
A60: April | M60: =SUM(M61:M79) -> 0 | N60: =SUM(N61:N79) -> 0 | O60: =AVERAGE(O61:O79) -> 0
O61: 0
A80: May | M80: =SUM(M81:M99) -> 0 | N80: =SUM(N81:N99) -> 0 | O80: =AVERAGE(O81:O99) -> 0
O81: 0
A100: June | M100: =SUM(M101:M119) -> 0 | N100: =SUM(N101:N119) -> 0 | O100: =AVERAGE(O101:O119) -> 0
O101: 0
A120: July | M120: =SUM(M121:M139) -> 0 | N120: =SUM(N121:N139) -> 0 | O120: =AVERAGE(O121:O139) -> 0
O121: 0
A140: August | M140: =SUM(M141:M159) -> 0 | N140: =SUM(N141:N159) -> 0 | O140: =AVERAGE(O141:O159) -> 0
O141: 0
A160: September | M160: =SUM(M161:M179) -> 0 | N160: =SUM(N161:N179) -> 0 | O160: =AVERAGE(O161:O179) -> 0
O161: 0
A180: October | M180: =SUM(M181:M199) -> 0 | N180: =SUM(N181:N199) -> 0 | O180: =AVERAGE(O181:O199) -> 0
O181: 0
A200: November | M200: =SUM(M201:M219) -> 0 | N200: =SUM(N201:N219) -> 0 | O200: =AVERAGE(O201:O219) -> 0
O201: 0
A220: December | M220: =SUM(M221:M239) -> 0 | N220: =SUM(N221:N239) -> 0 | O220: =AVERAGE(O221:O239) -> 0
...
